Workbook

Sheet START HERE
A1: UNIT ECONOMICS CALCULATOR
A3: LMOFID-inspired | Stage 9 — Student exercise / 3-product profitability
A5: 01 | EXERCISE SOLVED
A6: Exercise from slides 23–24; all five requested answers calculated.
A9: 02 | SIMULATOR
A10: Edit the gold-highlighted inputs; outputs update using formulas.
A13: 03 | FORMULAS & CONCEPTS
A14: COGS, CPL, confirmed/delivered orders, RTO, profit, margin and break-even.
A17: 04 | SCENARIO ANALYSIS
A18: Compare alternative CPL, confirmation, delivery rate and selling price.
A21: 05 | ASSUMPTIONS
A22: Explicitly identifies unspecified input data and model conventions.
... A38: V3 | 13-STEP PRACTICE LAB
A40: =HYPERLINK("#'PRACTICE A'!A1","PRACTICE A") -> PRACTICE A | B40: =HYPERLINK("#'PRACTICE B'!A1","PRACTICE B") -> PRACTICE B | C40: =HYPERLINK("#'PRACTICE C'!A1","PRACTICE C") -> PRACTICE C | D40: =HYPERLINK("#'EXERCISE A-B-C'!A1","EXERCISE A/B/C") -> EXERCISE A/B/C | E40: =HYPERLINK("#'COMPARE PRODUCTS'!A1","COMPARISON") -> COMPARISON

Sheet EXERCISE SOLVED
A1: STUDENT EXERCISE — RESOLVED
A3: Products A · B · C | MAD · yellow cells = editable assumptions
A5: INPUTS / ENTRÉES | B5: PRODUCT A | C5: PRODUCT B | D5: PRODUCT C
A6: Selling price / Prix de vente | B6: 199 | C6: 349 | D6: 599
A7: Product cost / Coût produit | B7: 35 | C7: 75 | D7: 120
A8: Packaging / Emballage | B8: 5 | C8: 10 | D8: 15
A9: Shipping / Livraison sortante | B9: 30 | C9: 35 | D9: 40
A10: CPL / Cost per lead | B10: 18 | C10: 25 | D10: 40
A11: Confirmation rate / Taux confirmation | B11: 0.65 | C11: 0.72 | D11: 0.78
A12: Delivery rate / Taux livraison | B12: 0.78 | C12: 0.83 | D12: 0.88
A13: Monthly fixed costs / Coûts fixes | B13: 2000 | C13: 3000 | D13: 5000
A14: Confirmation cost / Commande confirmée | B14: 3 | C14: 3 | D14: 3
A15: Return shipping cost / Retour | B15: 25 | C15: 25 | D15: 25
A16: Leads per day / Prospects par jour | B16: 22 | C16: 22 | D16: 22
A17: Days per month / Jours par mois | B17: 30 | C17: 30 | D17: 30
A19: UNIT ECONOMICS / CALCULS
A20: COGS per unit | B20: =SUM(B7:B9) -> 70 | C20: =SUM(C7:C9) -> 120 | D20: =SUM(D7:D9) -> 175
A21: Gross profit per unit | B21: =B6-B20 -> 129 | C21: =C6-C20 -> 229 | D21: =D6-D20 -> 424
A22: Gross margin | B22: =IFERROR(B21/B6,0) -> 0.64824121 | C22: =IFERROR(C21/C6,0) -> 0.65616046 | D22: =IFERROR(D21/D6,0) -> 0.70784641
A23: Confirmed leads per day | B23: =B16*B11 -> 14.3 | C23: =C16*C11 -> 15.84 | D23: =D16*D11 -> 17.16
A24: Delivered units per day | B24: =B23*B12 -> 11.154 | C24: =C23*C12 -> 13.1472 | D24: =D23*D12 -> 15.1008
A25: RTO rate | B25: =1-B12 -> 0.22 | C25: =1-C12 -> 0.17 | D25: =1-D12 -> 0.12
A26: Returned units per day | B26: =B23*B25 -> 3.146 | C26: =C23*C25 -> 2.6928 | D26: =D23*D25 -> 2.0592
A27: Effective ad cost / delivered unit | B27: =IFERROR(B10/(B11*B12),0) -> 35.502959 | C27: =IFERROR(C10/(C11*C12),0) -> 41.834003 | D27: =IFERROR(D10/(D11*D12),0) -> 58.275058
A28: Confirmation cost / delivered unit | B28: =IFERROR(B14/B12,0) -> 3.8461538 | C28: =IFERROR(C14/C12,0) -> 3.6144578 | D28: =IFERROR(D14/D12,0) -> 3.4090909
A29: Return cost / delivered unit | B29: =IFERROR(B15*B25/B12,0) -> 7.0512821 | C29: =IFERROR(C15*C25/C12,0) -> 5.1204819 | D29: =IFERROR(D15*D25/D12,0) -> 3.4090909
A30: Total variable cost / delivered unit | B30: =SUM(B20,B27:B29) -> 116.40039 | C30: =SUM(C20,C27:C29) -> 170.56894 | D30: =SUM(D20,D27:D29) -> 240.09324
A31: Contribution margin / delivered unit | B31: =B6-B30 -> 82.599606 | C31: =C6-C30 -> 178.43106 | D31: =D6-D30 -> 358.90676
A32: Contribution margin % | B32: =IFERROR(B31/B6,0) -> 0.41507339 | C32: =IFERROR(C31/C6,0) -> 0.51126378 | D32: =IFERROR(D31/D6,0) -> 0.59917656
A33: Monthly delivered units | B33: =B24*B17 -> 334.62 | C33: =C24*C17 -> 394.416 | D33: =D24*D17 -> 453.024
A34: Fixed cost / delivered unit | B34: =IFERROR(B13/B33,0) -> 5.9769291 | C34: =IFERROR(C13/C33,0) -> 7.6061823 | D34: =IFERROR(D13/D33,0) -> 11.036943
A35: Net profit / delivered unit | B35: =B31-B34 -> 76.622676 | C35: =C31-C34 -> 170.82488 | D35: =D31-D34 -> 347.86982
A36: Net margin % | B36: =IFERROR(B35/B6,0) -> 0.38503858 | C36: =IFERROR(C35/C6,0) -> 0.48946956 | D36: =IFERROR(D35/D6,0) -> 0.58075095
A37: Break-even units / month | B37: =IF(B31<=0,"N/A",ROUNDUP(B13/B31,0)) -> 25 | C37: =IF(C31<=0,"N/A",ROUNDUP(C13/C31,0)) -> 17 | D37: =IF(D31<=0,"N/A",ROUNDUP(D13/D31,0)) -> 14
A38: Break-even monthly revenue | B38: =IF(B31<=0,"N/A",B37*B6) -> 4975 | C38: =IF(C31<=0,"N/A",C37*C6) -> 5933 | D38: =IF(D31<=0,"N/A",D37*D6) -> 8386
A39: Monthly net profit | B39: =B33*B31-B13 -> 25639.48 | C39: =C33*C31-C13 -> 67376.064 | D39: =D33*D31-D13 -> 157593.38
A40: Net profit at break-even volume | B40: =IF(B31<=0,"N/A",B37*B31-B13) -> 64.990138 | C40: =IF(C31<=0,"N/A",C37*C31-C13) -> 33.327979 | D40: =IF(D31<=0,"N/A",D37*D31-D13) -> 24.694639
A42: RANKING / CONCLUSION
A43: BEST PRODUCT — MAX. NET PROFIT / UNIT | B43: =INDEX(B5:D5,1,MATCH(MAX(B35:D35),B35:D35,0)) -> PRODUCT C
A44: BEST PRODUCT — MONTHLY NET PROFIT | B44: =INDEX(B5:D5,1,MATCH(MAX(B39:D39),B39:D39,0)) -> PRODUCT C
...

Sheet SIMULATOR
A1: UNIT ECONOMICS — LIVE SIMULATOR
A3: Products A · B · C | MAD · yellow cells = editable assumptions
A5: INPUTS / ENTRÉES | B5: PRODUCT A | C5: PRODUCT B | D5: PRODUCT C
A6: Selling price / Prix de vente | B6: 199 | C6: 349 | D6: 599
A7: Product cost / Coût produit | B7: 35 | C7: 75 | D7: 120
A8: Packaging / Emballage | B8: 5 | C8: 10 | D8: 15
A9: Shipping / Livraison sortante | B9: 30 | C9: 35 | D9: 40
A10: CPL / Cost per lead | B10: 18 | C10: 25 | D10: 40
A11: Confirmation rate / Taux confirmation | B11: 0.65 | C11: 0.72 | D11: 0.78
A12: Delivery rate / Taux livraison | B12: 0.78 | C12: 0.83 | D12: 0.88
A13: Monthly fixed costs / Coûts fixes | B13: 2000 | C13: 3000 | D13: 5000
A14: Confirmation cost / Commande confirmée | B14: 3 | C14: 3 | D14: 3
A15: Return shipping cost / Retour | B15: 25 | C15: 25 | D15: 25
A16: Leads per day / Prospects par jour | B16: 22 | C16: 22 | D16: 22
A17: Days per month / Jours par mois | B17: 30 | C17: 30 | D17: 30
A19: UNIT ECONOMICS / CALCULS
A20: COGS per unit | B20: =SUM(B7:B9) -> 70 | C20: =SUM(C7:C9) -> 120 | D20: =SUM(D7:D9) -> 175
A21: Gross profit per unit | B21: =B6-B20 -> 129 | C21: =C6-C20 -> 229 | D21: =D6-D20 -> 424
A22: Gross margin | B22: =IFERROR(B21/B6,0) -> 0.64824121 | C22: =IFERROR(C21/C6,0) -> 0.65616046 | D22: =IFERROR(D21/D6,0) -> 0.70784641
A23: Confirmed leads per day | B23: =B16*B11 -> 14.3 | C23: =C16*C11 -> 15.84 | D23: =D16*D11 -> 17.16
A24: Delivered units per day | B24: =B23*B12 -> 11.154 | C24: =C23*C12 -> 13.1472 | D24: =D23*D12 -> 15.1008
A25: RTO rate | B25: =1-B12 -> 0.22 | C25: =1-C12 -> 0.17 | D25: =1-D12 -> 0.12
A26: Returned units per day | B26: =B23*B25 -> 3.146 | C26: =C23*C25 -> 2.6928 | D26: =D23*D25 -> 2.0592
A27: Effective ad cost / delivered unit | B27: =IFERROR(B10/(B11*B12),0) -> 35.502959 | C27: =IFERROR(C10/(C11*C12),0) -> 41.834003 | D27: =IFERROR(D10/(D11*D12),0) -> 58.275058
A28: Confirmation cost / delivered unit | B28: =IFERROR(B14/B12,0) -> 3.8461538 | C28: =IFERROR(C14/C12,0) -> 3.6144578 | D28: =IFERROR(D14/D12,0) -> 3.4090909
A29: Return cost / delivered unit | B29: =IFERROR(B15*B25/B12,0) -> 7.0512821 | C29: =IFERROR(C15*C25/C12,0) -> 5.1204819 | D29: =IFERROR(D15*D25/D12,0) -> 3.4090909
A30: Total variable cost / delivered unit | B30: =SUM(B20,B27:B29) -> 116.40039 | C30: =SUM(C20,C27:C29) -> 170.56894 | D30: =SUM(D20,D27:D29) -> 240.09324
A31: Contribution margin / delivered unit | B31: =B6-B30 -> 82.599606 | C31: =C6-C30 -> 178.43106 | D31: =D6-D30 -> 358.90676
A32: Contribution margin % | B32: =IFERROR(B31/B6,0) -> 0.41507339 | C32: =IFERROR(C31/C6,0) -> 0.51126378 | D32: =IFERROR(D31/D6,0) -> 0.59917656
A33: Monthly delivered units | B33: =B24*B17 -> 334.62 | C33: =C24*C17 -> 394.416 | D33: =D24*D17 -> 453.024
A34: Fixed cost / delivered unit | B34: =IFERROR(B13/B33,0) -> 5.9769291 | C34: =IFERROR(C13/C33,0) -> 7.6061823 | D34: =IFERROR(D13/D33,0) -> 11.036943
A35: Net profit / delivered unit | B35: =B31-B34 -> 76.622676 | C35: =C31-C34 -> 170.82488 | D35: =D31-D34 -> 347.86982
A36: Net margin % | B36: =IFERROR(B35/B6,0) -> 0.38503858 | C36: =IFERROR(C35/C6,0) -> 0.48946956 | D36: =IFERROR(D35/D6,0) -> 0.58075095
A37: Break-even units / month | B37: =IF(B31<=0,"N/A",ROUNDUP(B13/B31,0)) -> 25 | C37: =IF(C31<=0,"N/A",ROUNDUP(C13/C31,0)) -> 17 | D37: =IF(D31<=0,"N/A",ROUNDUP(D13/D31,0)) -> 14
A38: Break-even monthly revenue | B38: =IF(B31<=0,"N/A",B37*B6) -> 4975 | C38: =IF(C31<=0,"N/A",C37*C6) -> 5933 | D38: =IF(D31<=0,"N/A",D37*D6) -> 8386
A39: Monthly net profit | B39: =B33*B31-B13 -> 25639.48 | C39: =C33*C31-C13 -> 67376.064 | D39: =D33*D31-D13 -> 157593.38
A40: Net profit at break-even volume | B40: =IF(B31<=0,"N/A",B37*B31-B13) -> 64.990138 | C40: =IF(C31<=0,"N/A",C37*C31-C13) -> 33.327979 | D40: =IF(D31<=0,"N/A",D37*D31-D13) -> 24.694639
A42: RANKING / CONCLUSION
A43: BEST PRODUCT — MAX. NET PROFIT / UNIT | B43: =INDEX(B5:D5,1,MATCH(MAX(B35:D35),B35:D35,0)) -> PRODUCT C
A44: BEST PRODUCT — MONTHLY NET PROFIT | B44: =INDEX(B5:D5,1,MATCH(MAX(B39:D39),B39:D39,0)) -> PRODUCT C
...

Sheet FORMULAS & CONCEPTS
A1: FORMULAS & CONCEPTS
A3: Stage 1–9 | Definitions · Excel logic · bilingual terminology
A5: Concept | B5: Formula (business) | C5: Explanation | D5: Example (Product A) | E5: Reference
A6: COGS | B6: Product + packaging + shipping | C6: Direct fulfilment cost per sold unit | D6: =SUM(SIMULATOR!B7:B9) -> 70 | E6: Slide 6
A7: Gross Profit | B7: Selling price − COGS | C7: Gross earnings before advertising, RTO and overhead | D7: =SIMULATOR!B21 -> 129 | E7: Slide 7
A8: Gross Margin | B8: Gross profit ÷ price | C8: Gross profitability percentage | D8: =SIMULATOR!B22 -> 0.64824121 | E8: Slide 7
A9: CPL | B9: Ad spend ÷ leads | C9: Acquisition cost per unconfirmed lead | D9: =SIMULATOR!B10 -> 18 | E9: Slide 8
A10: Confirmed Orders | B10: Leads × confirmation rate | C10: Orders that pass validation | D10: =SIMULATOR!B23 -> 14.3 | E10: Slide 9
A11: Delivered Orders | B11: Confirmed × delivery rate | C11: Actually delivered units generating revenue | D11: =SIMULATOR!B24 -> 11.154 | E11: Slide 11
A12: RTO Rate | B12: 1 − delivery rate | C12: Share of confirmed orders that return/fail | D12: =SIMULATOR!B25 -> 0.22 | E12: Slide 12
A13: Effective Ad Cost | B13: CPL ÷ (confirmation × delivery) | C13: True ad spend per delivered unit | D13: =SIMULATOR!B27 -> 35.502959 | E13: Slides 10, 21
A14: Confirmation cost/unit | B14: Cost per confirmed ÷ delivery rate | C14: Allocate non-delivered confirmation attempts | D14: =SIMULATOR!B28 -> 3.8461538 | E14: Slide 15
A15: Returns cost/unit | B15: RTO × return shipping ÷ delivery rate | C15: Spread return losses across deliveries | D15: =SIMULATOR!B29 -> 7.0512821 | E15: Slides 12,15
A16: Contribution | B16: Selling price − all variable costs | C16: Amount per delivered unit to cover fixed expenses | D16: =SIMULATOR!B31 -> 82.599606 | E16: Slide 17
A17: Fixed cost/unit | B17: Monthly fixed ÷ monthly delivered units | C17: Fixed overhead allocation; depends on volume | D17: =SIMULATOR!B34 -> 5.9769291 | E17: Slide 14
A18: Net Profit per unit | B18: Contribution − fixed costs / unit | C18: Profit after advertising, RTO and allocated fixed | D18: =SIMULATOR!B35 -> 76.622676 | E18: Slide 15
A19: Net Margin | B19: Net profit per unit ÷ selling price | C19: Percent of revenue retained after costs | D19: =SIMULATOR!B36 -> 0.38503858 | E19: Slide 16
A20: Break-even units | B20: ROUNDUP(fixed ÷ contribution) | C20: Minimum whole delivered units to cover fixed costs | D20: =SIMULATOR!B37 -> 25 | E20: Slide 17
A21: Break-even revenue | B21: Break-even units × selling price | C21: Revenue at the integer break-even volume | D21: =SIMULATOR!B38 -> 4975 | E21: Slide 17
A22: Monthly net P&L | B22: Delivered units × contribution − fixed | C22: Forecast monthly total profit based on leads/day | D22: =SIMULATOR!B39 -> 25639.48 | E22: Slide 20

Sheet SCENARIO ANALYSIS
A1: SCENARIO ANALYSIS
A3: Sensitivity | Product A base case and alternative operating assumptions
A5: Scenario | B5: Price | C5: CPL | D5: Confirm % | E5: Deliver % | F5: Variable cost | G5: Contribution | H5: Net/unit | I5: Monthly net
A6: BASE CASE | B6: =SIMULATOR!B6 -> 199 | C6: =SIMULATOR!B10 -> 18 | D6: =SIMULATOR!B11 -> 0.65 | E6: =SIMULATOR!B12 -> 0.78 | F6: =SIMULATOR!B20+IFERROR(C6/(D6*E6),0)+IFERROR(SIMULATOR!B14/E6,0)+IFERROR(SIMULATOR!B15*(1-E6)/E6,0) -> 116.40039 | G6: =B6-F6 -> 82.599606 | H6: =G6-IFERROR(SIMULATOR!B13/(SIMULATOR!B16*D6*E6*SIMULATOR!B17),0) -> 76.622676 | I6: =G6*SIMULATOR!B16*D6*E6*SIMULATOR!B17-SIMULATOR!B13 -> 25639.48
A7: CPL improves | B7: =SIMULATOR!B6 -> 199 | C7: =SIMULATOR!B10-5 -> 13 | D7: =SIMULATOR!B11 -> 0.65 | E7: =SIMULATOR!B12 -> 0.78 | F7: =SIMULATOR!B20+IFERROR(C7/(D7*E7),0)+IFERROR(SIMULATOR!B14/E7,0)+IFERROR(SIMULATOR!B15*(1-E7)/E7,0) -> 106.53846 | G7: =B7-F7 -> 92.461538 | H7: =G7-IFERROR(SIMULATOR!B13/(SIMULATOR!B16*D7*E7*SIMULATOR!B17),0) -> 86.484609 | I7: =G7*SIMULATOR!B16*D7*E7*SIMULATOR!B17-SIMULATOR!B13 -> 28939.48
A8: CPL worsens | B8: =SIMULATOR!B6 -> 199 | C8: =SIMULATOR!B10+5 -> 23 | D8: =SIMULATOR!B11 -> 0.65 | E8: =SIMULATOR!B12 -> 0.78 | F8: =SIMULATOR!B20+IFERROR(C8/(D8*E8),0)+IFERROR(SIMULATOR!B14/E8,0)+IFERROR(SIMULATOR!B15*(1-E8)/E8,0) -> 126.26233 | G8: =B8-F8 -> 72.737673 | H8: =G8-IFERROR(SIMULATOR!B13/(SIMULATOR!B16*D8*E8*SIMULATOR!B17),0) -> 66.760744 | I8: =G8*SIMULATOR!B16*D8*E8*SIMULATOR!B17-SIMULATOR!B13 -> 22339.48
A9: Confirm improves | B9: =SIMULATOR!B6 -> 199 | C9: =SIMULATOR!B10 -> 18 | D9: =SIMULATOR!B11+0.08 -> 0.73 | E9: =SIMULATOR!B12 -> 0.78 | F9: =SIMULATOR!B20+IFERROR(C9/(D9*E9),0)+IFERROR(SIMULATOR!B14/E9,0)+IFERROR(SIMULATOR!B15*(1-E9)/E9,0) -> 112.50966 | G9: =B9-F9 -> 86.490341 | H9: =G9-IFERROR(SIMULATOR!B13/(SIMULATOR!B16*D9*E9*SIMULATOR!B17),0) -> 81.168418 | I9: =G9*SIMULATOR!B16*D9*E9*SIMULATOR!B17-SIMULATOR!B13 -> 30503.416
A10: Confirm worsens | B10: =SIMULATOR!B6 -> 199 | C10: =SIMULATOR!B10 -> 18 | D10: =SIMULATOR!B11-0.08 -> 0.57 | E10: =SIMULATOR!B12 -> 0.78 | F10: =SIMULATOR!B20+IFERROR(C10/(D10*E10),0)+IFERROR(SIMULATOR!B14/E10,0)+IFERROR(SIMULATOR!B15*(1-E10)/E10,0) -> 121.38327 | G10: =B10-F10 -> 77.616734 | H10: =G10-IFERROR(SIMULATOR!B13/(SIMULATOR!B16*D10*E10*SIMULATOR!B17),0) -> 70.800938 | I10: =G10*SIMULATOR!B16*D10*E10*SIMULATOR!B17-SIMULATOR!B13 -> 20775.544
A11: Delivery improves | B11: =SIMULATOR!B6 -> 199 | C11: =SIMULATOR!B10 -> 18 | D11: =SIMULATOR!B11 -> 0.65 | E11: =SIMULATOR!B12+0.08 -> 0.86 | F11: =SIMULATOR!B20+IFERROR(C11/(D11*E11),0)+IFERROR(SIMULATOR!B14/E11,0)+IFERROR(SIMULATOR!B15*(1-E11)/E11,0) -> 109.7585 | G11: =B11-F11 -> 89.241503 | H11: =G11-IFERROR(SIMULATOR!B13/(SIMULATOR!B16*D11*E11*SIMULATOR!B17),0) -> 83.820567 | I11: =G11*SIMULATOR!B16*D11*E11*SIMULATOR!B17-SIMULATOR!B13 -> 30924.76
A12: Delivery worsens | B12: =SIMULATOR!B6 -> 199 | C12: =SIMULATOR!B10 -> 18 | D12: =SIMULATOR!B11 -> 0.65 | E12: =SIMULATOR!B12-0.08 -> 0.7 | F12: =SIMULATOR!B20+IFERROR(C12/(D12*E12),0)+IFERROR(SIMULATOR!B14/E12,0)+IFERROR(SIMULATOR!B15*(1-E12)/E12,0) -> 124.56044 | G12: =B12-F12 -> 74.43956 | H12: =G12-IFERROR(SIMULATOR!B13/(SIMULATOR!B16*D12*E12*SIMULATOR!B17),0) -> 67.779554 | I12: =G12*SIMULATOR!B16*D12*E12*SIMULATOR!B17-SIMULATOR!B13 -> 20354.2
A13: Price +50 MAD | B13: =SIMULATOR!B6+50 -> 249 | C13: =SIMULATOR!B10 -> 18 | D13: =SIMULATOR!B11 -> 0.65 | E13: =SIMULATOR!B12 -> 0.78 | F13: =SIMULATOR!B20+IFERROR(C13/(D13*E13),0)+IFERROR(SIMULATOR!B14/E13,0)+IFERROR(SIMULATOR!B15*(1-E13)/E13,0) -> 116.40039 | G13: =B13-F13 -> 132.59961 | H13: =G13-IFERROR(SIMULATOR!B13/(SIMULATOR!B16*D13*E13*SIMULATOR!B17),0) -> 126.62268 | I13: =G13*SIMULATOR!B16*D13*E13*SIMULATOR!B17-SIMULATOR!B13 -> 42370.48
A14: Price -50 MAD | B14: =SIMULATOR!B6-50 -> 149 | C14: =SIMULATOR!B10 -> 18 | D14: =SIMULATOR!B11 -> 0.65 | E14: =SIMULATOR!B12 -> 0.78 | F14: =SIMULATOR!B20+IFERROR(C14/(D14*E14),0)+IFERROR(SIMULATOR!B14/E14,0)+IFERROR(SIMULATOR!B15*(1-E14)/E14,0) -> 116.40039 | G14: =B14-F14 -> 32.599606 | H14: =G14-IFERROR(SIMULATOR!B13/(SIMULATOR!B16*D14*E14*SIMULATOR!B17),0) -> 26.622676 | I14: =G14*SIMULATOR!B16*D14*E14*SIMULATOR!B17-SIMULATOR!B13 -> 8908.48
A17: All scenario values are formula-linked to the SIMULATOR Product A input column.
A18: Net/unit includes volume-dependent fixed overhead; monthly P&L recalculates expected delivered units.

Sheet ASSUMPTIONS
A1: MODEL ASSUMPTIONS
A3: Transparency matters: distinguish exercise inputs from reused deck examples
A5: Parameter | B5: Default | C5: Origin | D5: Comment
A6: Confirmation cost per confirmed order | B6: 3 | C6: Slide 13 | D6: Modeled as cost per confirmed order; amortized across delivered orders.
A7: Return shipping / RTO cost | B7: 25 | C7: Slide 12 | D7: 25 MAD per returned order; not specified in exercise table.
A8: Days per month | B8: 30 | C8: Slide 14 | D8: Monthly volume based on 30 days.
A9: Lead volume per day | B9: 22 | C9: Slide 8 | D9: Needed only for optional monthly P&L, not unit break-even.
A10: Product shipping as COGS | B10: Included | C10: Slide 6 | D10: COGS = product cost + packaging + outbound shipping.
A11: Returns | B11: Confirmed but not delivered | C11: Slides 11–12 | D11: RTO count = confirmed orders × (1 − delivery rate).
A12: Advertising denominator | B12: Delivered units | C12: Slides 10, 15 and 21 | D12: Effective advertising cost = CPL ÷ confirmation rate ÷ delivery rate.
A13: Contribution | B13: Before fixed costs | C13: Slide 17 | D13: Price − variable cost per delivered unit.
A14: Profit after fixed per unit | B14: Volume-dependent | C14: Slides 14–15 | D14: Net profit per unit includes allocated monthly fixed costs.
A15: Break-even units | B15: Rounded up | C15: Slide 17 | D15: CEILING(monthly fixed costs / contribution margin, 1).
A16: Volume requirement | B16: Optional | C16: Slides 8, 11 and 14 | D16: Monthly volume = leads/day × confirm rate × deliver rate × days/month.

Sheet PRACTICE A
A1: LMOFID ACADEMY | PRACTICE PRODUCT A
A3: 15 STEP CARDS • 13 original V3 steps + Confirmation and Variable Cost
A5: =HYPERLINK("#'PRACTICE A'!A1","PRODUCT A") -> PRODUCT A | C5: =HYPERLINK("#'PRACTICE B'!A1","PRODUCT B") -> PRODUCT B | E5: =HYPERLINK("#'PRACTICE C'!A1","PRODUCT C") -> PRODUCT C | G5: =HYPERLINK("#'COMPARE PRODUCTS'!A1","COMPARE") -> COMPARE
A7: PRODUCT DATA • LINKED INPUTS | E7: EXERCISE NAVIGATION
A9: Selling price | C9: =SIMULATOR!B6 -> 199 | E9: =HYPERLINK("#'EXERCISE A-B-C'!A1","EXERCISE A/B/C") -> EXERCISE A/B/C | G9: =HYPERLINK("#'FORMULAS & CONCEPTS'!A1","FORMULAS") -> FORMULAS
A10: CPL | C10: =SIMULATOR!B10 -> 18
A11: Monthly fixed | C11: =SIMULATOR!B13 -> 2000 | E11: Given units / month | H11: =SIMULATOR!B33 -> 334.62
E12: Change H11 to test a volume
A15: STEP 01 | COGS | E15: STEP 02 | GROSS PROFIT
A16: Product + Packaging + Shipping | E16: Selling Price − COGS
A17: AUTO FORMULA → | C17: =SUM(SIMULATOR!B7:B9) -> 70 | E17: AUTO FORMULA → | G17: =SIMULATOR!B6-C17 -> 129
A20: STEP 03 | GROSS MARGIN | E20: STEP 04 | LEADS / DAY
A21: Gross Profit ÷ Selling Price | E21: Ad Spend ÷ CPL
A22: AUTO FORMULA → | C22: =IFERROR(G17/SIMULATOR!B6,0) -> 0.64824121 | E22: AUTO FORMULA → | G22: =SIMULATOR!B16 -> 22
A25: STEP 05 | CONFIRMED ORDERS | E25: STEP 06 | DELIVERED ORDERS
A26: Leads × Confirmation Rate | E26: Confirmed × Delivery Rate
A27: AUTO FORMULA → | C27: =G22*SIMULATOR!B11 -> 14.3 | E27: AUTO FORMULA → | G27: =C27*SIMULATOR!B12 -> 11.154
A30: STEP 07 | RTO RATE | E30: STEP 08 | EFFECTIVE AD COST / DELIVERED
A31: 1 − Delivery Rate | E31: CPL ÷ Confirmation ÷ Delivery
A32: AUTO FORMULA → | C32: =1-SIMULATOR!B12 -> 0.22 | E32: AUTO FORMULA → | G32: =IFERROR(SIMULATOR!B10/(SIMULATOR!B11*SIMULATOR!B12),0) -> 35.502959
A35: STEP 09 | CONFIRMATION COST / DELIVERED | E35: STEP 10 | RETURN COST / DELIVERED
A36: Confirmed × Confirmation Cost ÷ Delivered | E36: Returns × Return Shipping Cost ÷ Delivered
A37: AUTO FORMULA → | C37: =IFERROR(C27*SIMULATOR!B14/G27,0) -> 3.8461538 | E37: AUTO FORMULA → | G37: =IFERROR((C27-G27)*SIMULATOR!B15/G27,0) -> 7.0512821
A40: STEP 11 | VARIABLE COST / DELIVERED | E40: STEP 12 | CONTRIBUTION / DELIVERED
A41: COGS + Ad + Confirmation + Returns | E41: Selling Price − Variable Cost
A42: AUTO FORMULA → | C42: =SUM(C17,G32,C37,G37) -> 116.40039 | E42: AUTO FORMULA → | G42: =SIMULATOR!B6-C42 -> 82.599606
A45: STEP 13 | NET PROFIT / DELIVERED
A46: Contribution − Fixed Cost / Delivered
A47: AUTO FORMULA → | C47: =G42-IFERROR(SIMULATOR!B13/(G27*SIMULATOR!B17),0) -> 76.622676
A51: MODEL: 15 linked calculations • V3 card design • no dual-result columns
A55: STEP 14 | BREAK-EVEN UNITS | E55: STEP 15 | VALUE GIVEN UNITS
A56: ROUNDUP(Fixed Costs ÷ Contribution, 0) | E56: Contribution × given units − Monthly fixed
A57: AUTO FORMULA → | C57: =IF(G42<=0,"N/A",ROUNDUP(SIMULATOR!B13/G42,0)) -> 25 | E57: AUTO FORMULA → | G57: =G42*$H$11-SIMULATOR!B13 -> 25639.48

Sheet PRACTICE B
A1: LMOFID ACADEMY | PRACTICE PRODUCT B
A3: 15 STEP CARDS • 13 original V3 steps + Confirmation and Variable Cost
A5: =HYPERLINK("#'PRACTICE A'!A1","PRODUCT A") -> PRODUCT A | C5: =HYPERLINK("#'PRACTICE B'!A1","PRODUCT B") -> PRODUCT B | E5: =HYPERLINK("#'PRACTICE C'!A1","PRODUCT C") -> PRODUCT C | G5: =HYPERLINK("#'COMPARE PRODUCTS'!A1","COMPARE") -> COMPARE
A7: PRODUCT DATA • LINKED INPUTS | E7: EXERCISE NAVIGATION
A9: Selling price | C9: =SIMULATOR!C6 -> 349 | E9: =HYPERLINK("#'EXERCISE A-B-C'!A1","EXERCISE A/B/C") -> EXERCISE A/B/C | G9: =HYPERLINK("#'FORMULAS & CONCEPTS'!A1","FORMULAS") -> FORMULAS
A10: CPL | C10: =SIMULATOR!C10 -> 25
A11: Monthly fixed | C11: =SIMULATOR!C13 -> 3000 | E11: Given units / month | H11: =SIMULATOR!C33 -> 394.416
E12: Change H11 to test a volume
A15: STEP 01 | COGS | E15: STEP 02 | GROSS PROFIT
A16: Product + Packaging + Shipping | E16: Selling Price − COGS
A17: AUTO FORMULA → | C17: =SUM(SIMULATOR!C7:C9) -> 120 | E17: AUTO FORMULA → | G17: =SIMULATOR!C6-C17 -> 229
A20: STEP 03 | GROSS MARGIN | E20: STEP 04 | LEADS / DAY
A21: Gross Profit ÷ Selling Price | E21: Ad Spend ÷ CPL
A22: AUTO FORMULA → | C22: =IFERROR(G17/SIMULATOR!C6,0) -> 0.65616046 | E22: AUTO FORMULA → | G22: =SIMULATOR!C16 -> 22
A25: STEP 05 | CONFIRMED ORDERS | E25: STEP 06 | DELIVERED ORDERS
A26: Leads × Confirmation Rate | E26: Confirmed × Delivery Rate
A27: AUTO FORMULA → | C27: =G22*SIMULATOR!C11 -> 15.84 | E27: AUTO FORMULA → | G27: =C27*SIMULATOR!C12 -> 13.1472
A30: STEP 07 | RTO RATE | E30: STEP 08 | EFFECTIVE AD COST / DELIVERED
A31: 1 − Delivery Rate | E31: CPL ÷ Confirmation ÷ Delivery
A32: AUTO FORMULA → | C32: =1-SIMULATOR!C12 -> 0.17 | E32: AUTO FORMULA → | G32: =IFERROR(SIMULATOR!C10/(SIMULATOR!C11*SIMULATOR!C12),0) -> 41.834003
A35: STEP 09 | CONFIRMATION COST / DELIVERED | E35: STEP 10 | RETURN COST / DELIVERED
A36: Confirmed × Confirmation Cost ÷ Delivered | E36: Returns × Return Shipping Cost ÷ Delivered
A37: AUTO FORMULA → | C37: =IFERROR(C27*SIMULATOR!C14/G27,0) -> 3.6144578 | E37: AUTO FORMULA → | G37: =IFERROR((C27-G27)*SIMULATOR!C15/G27,0) -> 5.1204819
A40: STEP 11 | VARIABLE COST / DELIVERED | E40: STEP 12 | CONTRIBUTION / DELIVERED
A41: COGS + Ad + Confirmation + Returns | E41: Selling Price − Variable Cost
A42: AUTO FORMULA → | C42: =SUM(C17,G32,C37,G37) -> 170.56894 | E42: AUTO FORMULA → | G42: =SIMULATOR!C6-C42 -> 178.43106
A45: STEP 13 | NET PROFIT / DELIVERED
A46: Contribution − Fixed Cost / Delivered
A47: AUTO FORMULA → | C47: =G42-IFERROR(SIMULATOR!C13/(G27*SIMULATOR!C17),0) -> 170.82488
A51: MODEL: 15 linked calculations • V3 card design • no dual-result columns
A55: STEP 14 | BREAK-EVEN UNITS | E55: STEP 15 | VALUE GIVEN UNITS
A56: ROUNDUP(Fixed Costs ÷ Contribution, 0) | E56: Contribution × given units − Monthly fixed
A57: AUTO FORMULA → | C57: =IF(G42<=0,"N/A",ROUNDUP(SIMULATOR!C13/G42,0)) -> 17 | E57: AUTO FORMULA → | G57: =G42*$H$11-SIMULATOR!C13 -> 67376.064

Sheet PRACTICE C
A1: LMOFID ACADEMY | PRACTICE PRODUCT C
A3: 15 STEP CARDS • 13 original V3 steps + Confirmation and Variable Cost
A5: =HYPERLINK("#'PRACTICE A'!A1","PRODUCT A") -> PRODUCT A | C5: =HYPERLINK("#'PRACTICE B'!A1","PRODUCT B") -> PRODUCT B | E5: =HYPERLINK("#'PRACTICE C'!A1","PRODUCT C") -> PRODUCT C | G5: =HYPERLINK("#'COMPARE PRODUCTS'!A1","COMPARE") -> COMPARE
A7: PRODUCT DATA • LINKED INPUTS | E7: EXERCISE NAVIGATION
A9: Selling price | C9: =SIMULATOR!D6 -> 599 | E9: =HYPERLINK("#'EXERCISE A-B-C'!A1","EXERCISE A/B/C") -> EXERCISE A/B/C | G9: =HYPERLINK("#'FORMULAS & CONCEPTS'!A1","FORMULAS") -> FORMULAS
A10: CPL | C10: =SIMULATOR!D10 -> 40
A11: Monthly fixed | C11: =SIMULATOR!D13 -> 5000 | E11: Given units / month | H11: =SIMULATOR!D33 -> 453.024
E12: Change H11 to test a volume
A15: STEP 01 | COGS | E15: STEP 02 | GROSS PROFIT
A16: Product + Packaging + Shipping | E16: Selling Price − COGS
A17: AUTO FORMULA → | C17: =SUM(SIMULATOR!D7:D9) -> 175 | E17: AUTO FORMULA → | G17: =SIMULATOR!D6-C17 -> 424
A20: STEP 03 | GROSS MARGIN | E20: STEP 04 | LEADS / DAY
A21: Gross Profit ÷ Selling Price | E21: Ad Spend ÷ CPL
A22: AUTO FORMULA → | C22: =IFERROR(G17/SIMULATOR!D6,0) -> 0.70784641 | E22: AUTO FORMULA → | G22: =SIMULATOR!D16 -> 22
A25: STEP 05 | CONFIRMED ORDERS | E25: STEP 06 | DELIVERED ORDERS
A26: Leads × Confirmation Rate | E26: Confirmed × Delivery Rate
A27: AUTO FORMULA → | C27: =G22*SIMULATOR!D11 -> 17.16 | E27: AUTO FORMULA → | G27: =C27*SIMULATOR!D12 -> 15.1008
A30: STEP 07 | RTO RATE | E30: STEP 08 | EFFECTIVE AD COST / DELIVERED
A31: 1 − Delivery Rate | E31: CPL ÷ Confirmation ÷ Delivery
A32: AUTO FORMULA → | C32: =1-SIMULATOR!D12 -> 0.12 | E32: AUTO FORMULA → | G32: =IFERROR(SIMULATOR!D10/(SIMULATOR!D11*SIMULATOR!D12),0) -> 58.275058
A35: STEP 09 | CONFIRMATION COST / DELIVERED | E35: STEP 10 | RETURN COST / DELIVERED
A36: Confirmed × Confirmation Cost ÷ Delivered | E36: Returns × Return Shipping Cost ÷ Delivered
A37: AUTO FORMULA → | C37: =IFERROR(C27*SIMULATOR!D14/G27,0) -> 3.4090909 | E37: AUTO FORMULA → | G37: =IFERROR((C27-G27)*SIMULATOR!D15/G27,0) -> 3.4090909
A40: STEP 11 | VARIABLE COST / DELIVERED | E40: STEP 12 | CONTRIBUTION / DELIVERED
A41: COGS + Ad + Confirmation + Returns | E41: Selling Price − Variable Cost
A42: AUTO FORMULA → | C42: =SUM(C17,G32,C37,G37) -> 240.09324 | E42: AUTO FORMULA → | G42: =SIMULATOR!D6-C42 -> 358.90676
A45: STEP 13 | NET PROFIT / DELIVERED
A46: Contribution − Fixed Cost / Delivered
A47: AUTO FORMULA → | C47: =G42-IFERROR(SIMULATOR!D13/(G27*SIMULATOR!D17),0) -> 347.86982
A51: MODEL: 15 linked calculations • V3 card design • no dual-result columns
A55: STEP 14 | BREAK-EVEN UNITS | E55: STEP 15 | VALUE GIVEN UNITS
A56: ROUNDUP(Fixed Costs ÷ Contribution, 0) | E56: Contribution × given units − Monthly fixed
A57: AUTO FORMULA → | C57: =IF(G42<=0,"N/A",ROUNDUP(SIMULATOR!D13/G42,0)) -> 14 | E57: AUTO FORMULA → | G57: =G42*$H$11-SIMULATOR!D13 -> 157593.38

Sheet EXERCISE A-B-C
A1: EXERCISE A / B / C
A4: =HYPERLINK("#'PRACTICE A'!A1","PRACTICE A") -> PRACTICE A | C4: =HYPERLINK("#'PRACTICE B'!A1","PRACTICE B") -> PRACTICE B | E4: =HYPERLINK("#'PRACTICE C'!A1","PRACTICE C") -> PRACTICE C | G4: =HYPERLINK("#'COMPARE PRODUCTS'!A1","COMPARE") -> COMPARE
A8: SOURCE INPUT | B8: PRODUCT A | C8: PRODUCT B | D8: PRODUCT C
A9: Selling Price | B9: =SIMULATOR!B6 -> 199 | C9: =SIMULATOR!C6 -> 349 | D9: =SIMULATOR!D6 -> 599
A10: Product Cost | B10: =SIMULATOR!B7 -> 35 | C10: =SIMULATOR!C7 -> 75 | D10: =SIMULATOR!D7 -> 120
A11: Packaging | B11: =SIMULATOR!B8 -> 5 | C11: =SIMULATOR!C8 -> 10 | D11: =SIMULATOR!D8 -> 15
A12: Shipping | B12: =SIMULATOR!B9 -> 30 | C12: =SIMULATOR!C9 -> 35 | D12: =SIMULATOR!D9 -> 40
A13: CPL | B13: =SIMULATOR!B10 -> 18 | C13: =SIMULATOR!C10 -> 25 | D13: =SIMULATOR!D10 -> 40
A14: Confirmation rate | B14: =SIMULATOR!B11 -> 0.65 | C14: =SIMULATOR!C11 -> 0.72 | D14: =SIMULATOR!D11 -> 0.78
A15: Delivery rate | B15: =SIMULATOR!B12 -> 0.78 | C15: =SIMULATOR!C12 -> 0.83 | D15: =SIMULATOR!D12 -> 0.88
A16: Fixed costs | B16: =SIMULATOR!B13 -> 2000 | C16: =SIMULATOR!C13 -> 3000 | D16: =SIMULATOR!D13 -> 5000
B19: =HYPERLINK("#'PRACTICE A'!A1","PRACTICE PRODUCT A") -> PRACTICE PRODUCT A | C19: =HYPERLINK("#'PRACTICE B'!A1","PRACTICE PRODUCT B") -> PRACTICE PRODUCT B | D19: =HYPERLINK("#'PRACTICE C'!A1","PRACTICE PRODUCT C") -> PRACTICE PRODUCT C
B23: =HYPERLINK("#'COMPARE PRODUCTS'!A1","COMPARE RESULTS") -> COMPARE RESULTS
A26: All product data are linked from the original SIMULATOR sheet — no check answers.

Sheet COMPARE PRODUCTS
A1: 4. COMPARE PRODUCTS
A4: =HYPERLINK("#'PRACTICE A'!A1","PRACTICE A") -> PRACTICE A | C4: =HYPERLINK("#'PRACTICE B'!A1","PRACTICE B") -> PRACTICE B | E4: =HYPERLINK("#'PRACTICE C'!A1","PRACTICE C") -> PRACTICE C | G4: =HYPERLINK("#'COMPARE PRODUCTS'!A1","COMPARE") -> COMPARE
A8: INDICATOR | B8: PRODUCT A | C8: PRODUCT B | D8: PRODUCT C
A9: Selling Price | B9: =SIMULATOR!B6 -> 199 | C9: =SIMULATOR!C6 -> 349 | D9: =SIMULATOR!D6 -> 599
A10: COGS | B10: ='PRACTICE A'!C17 -> 70 | C10: ='PRACTICE B'!C17 -> 120 | D10: ='PRACTICE C'!C17 -> 175
A11: Gross Profit | B11: ='PRACTICE A'!G17 -> 129 | C11: ='PRACTICE B'!G17 -> 229 | D11: ='PRACTICE C'!G17 -> 424
A12: Gross Margin | B12: ='PRACTICE A'!C22 -> 0.64824121 | C12: ='PRACTICE B'!C22 -> 0.65616046 | D12: ='PRACTICE C'!C22 -> 0.70784641
A13: Confirmed Orders/day | B13: ='PRACTICE A'!C27 -> 14.3 | C13: ='PRACTICE B'!C27 -> 15.84 | D13: ='PRACTICE C'!C27 -> 17.16
A14: Delivered Orders/day | B14: ='PRACTICE A'!G27 -> 11.154 | C14: ='PRACTICE B'!G27 -> 13.1472 | D14: ='PRACTICE C'!G27 -> 15.1008
A15: Effective Ad Cost / Delivered | B15: ='PRACTICE A'!G32 -> 35.502959 | C15: ='PRACTICE B'!G32 -> 41.834003 | D15: ='PRACTICE C'!G32 -> 58.275058
A16: Confirmation Cost / Delivered | B16: ='PRACTICE A'!C37 -> 3.8461538 | C16: ='PRACTICE B'!C37 -> 3.6144578 | D16: ='PRACTICE C'!C37 -> 3.4090909
A17: Return Cost / Delivered | B17: ='PRACTICE A'!G37 -> 7.0512821 | C17: ='PRACTICE B'!G37 -> 5.1204819 | D17: ='PRACTICE C'!G37 -> 3.4090909
A18: Variable Cost / Delivered | B18: ='PRACTICE A'!C42 -> 116.40039 | C18: ='PRACTICE B'!C42 -> 170.56894 | D18: ='PRACTICE C'!C42 -> 240.09324
A19: Contribution / Delivered | B19: ='PRACTICE A'!G42 -> 82.599606 | C19: ='PRACTICE B'!G42 -> 178.43106 | D19: ='PRACTICE C'!G42 -> 358.90676
A20: Net Profit / Delivered | B20: ='PRACTICE A'!C47 -> 76.622676 | C20: ='PRACTICE B'!C47 -> 170.82488 | D20: ='PRACTICE C'!C47 -> 347.86982
A21: Break-Even Units | B21: ='PRACTICE A'!C57 -> 25 | C21: ='PRACTICE B'!C57 -> 17 | D21: ='PRACTICE C'!C57 -> 14
A22: Value Given Units | B22: ='PRACTICE A'!G57 -> 25639.48 | C22: ='PRACTICE B'!G57 -> 67376.064 | D22: ='PRACTICE C'!G57 -> 157593.38
A23: Net Profit at Break-Even Volume | B23: =B21*B19-SIMULATOR!B13 -> 64.990138 | C23: =C21*C19-SIMULATOR!C13 -> 33.327979 | D23: =D21*D19-SIMULATOR!D13 -> 24.694639
A25: WINNER BY CRITERION | B25: PRODUCT
A26: Best Net Profit / Delivered | B26: =INDEX($B$8:$D$8,1,MATCH(MAX(B20:D20),B20:D20,0)) -> PRODUCT C
A27: Lowest Break-Even Units | B27: =INDEX($B$8:$D$8,1,MATCH(MIN(B21:D21),B21:D21,0)) -> PRODUCT C
A28: Highest Value Given Units | B28: =INDEX($B$8:$D$8,1,MATCH(MAX(B22:D22),B22:D22,0)) -> PRODUCT C
